{"trial_id": "0174", "hyperparameters": {"space": [{"class_name": "Choice", "config": {"name": "activation", "default": "relu", "conditions": [], "values": ["relu", "tanh"], "ordered": false}}, {"class_name": "Int", "config": {"name": "first_units", "default": null, "conditions": [], "min_value": 1, "max_value": 10, "step": 2, "sampling": "linear"}}, {"class_name": "Int", "config": {"name": "num_layers", "default": null, "conditions": [], "min_value": 1, "max_value": 4, "step": 1, "sampling": "linear"}}, {"class_name": "Int", "config": {"name": "units_0", "default": null, "conditions": [], "min_value": 1, "max_value": 10, "step": 2, "sampling": "linear"}}, {"class_name": "Int", "config": {"name": "units_1", "default": null, "conditions": [], "min_value": 1, "max_value": 10, "step": 2, "sampling": "linear"}}, {"class_name": "Int", "config": {"name": "units_2", "default": null, "conditions": [], "min_value": 1, "max_value": 10, "step": 2, "sampling": "linear"}}, {"class_name": "Int", "config": {"name": "units_3", "default": null, "conditions": [], "min_value": 1, "max_value": 10, "step": 2, "sampling": "linear"}}], "values": {"activation": "relu", "first_units": 9, "num_layers": 1, "units_0": 9, "units_1": 7, "units_2": 9, "units_3": 5, "tuner/epochs": 50, "tuner/initial_epoch": 17, "tuner/bracket": 1, "tuner/round": 1, "tuner/trial_id": "0168"}}, "metrics": {"metrics": {}}, "score": null, "best_step": 0, "status": "FAILED", "message": "Traceback (most recent call last):\n  File \"C:\\Users\\erico\\anaconda3\\envs\\PythonData\\lib\\site-packages\\keras_tuner\\engine\\base_tuner.py\", line 250, in _try_run_and_update_trial\n    self._run_and_update_trial(trial, *fit_args, **fit_kwargs)\n  File \"C:\\Users\\erico\\anaconda3\\envs\\PythonData\\lib\\site-packages\\keras_tuner\\engine\\base_tuner.py\", line 215, in _run_and_update_trial\n    results = self.run_trial(trial, *fit_args, **fit_kwargs)\n  File \"C:\\Users\\erico\\anaconda3\\envs\\PythonData\\lib\\site-packages\\keras_tuner\\tuners\\hyperband.py\", line 404, in run_trial\n    return super().run_trial(trial, *fit_args, **fit_kwargs)\n  File \"C:\\Users\\erico\\anaconda3\\envs\\PythonData\\lib\\site-packages\\keras_tuner\\engine\\tuner.py\", line 286, in run_trial\n    obj_value = self._build_and_fit_model(trial, *args, **copied_kwargs)\n  File \"C:\\Users\\erico\\anaconda3\\envs\\PythonData\\lib\\site-packages\\keras_tuner\\engine\\tuner.py\", line 213, in _build_and_fit_model\n    results = self.hypermodel.fit(hp, model, *args, **kwargs)\n  File \"C:\\Users\\erico\\anaconda3\\envs\\PythonData\\lib\\site-packages\\keras_tuner\\engine\\hypermodel.py\", line 144, in fit\n    return model.fit(*args, **kwargs)\n  File \"C:\\Users\\erico\\anaconda3\\envs\\PythonData\\lib\\site-packages\\keras\\utils\\traceback_utils.py\", line 70, in error_handler\n    raise e.with_traceback(filtered_tb) from None\n  File \"C:\\Users\\erico\\anaconda3\\envs\\PythonData\\lib\\site-packages\\tensorflow\\python\\eager\\execute.py\", line 53, in quick_execute\n    inputs, attrs, num_outputs)\ntensorflow.python.framework.errors_impl.FailedPreconditionError: {{function_node __wrapped__MergeV2Checkpoints_device_/job:localhost/replica:0/task:0/device:CPU:0}} Failed to rename: project\\untitled_project\\trial_0174\\checkpoint_temp/part-00000-of-00001.data-00000-of-00001 to: project\\untitled_project\\trial_0174\\checkpoint.data-00000-of-00001 : The process cannot access the file because it is being used by another process.\r\n; Broken pipe [Op:MergeV2Checkpoints]\n"}